Workbook

Sheet Sheet1

Sheet Extractions
A1: ID | B1: Title | C1: Author(s) | D1: Affliation | E1: Year | F1: Country | G1: Database | H1: Publisher | I1: Publication Venue | J1: Document Type | K1: Citation count | L1: Abstract | M1: Main Contribution | N1: Applications | O1: Evaluated Product | P1: Participantns Sample size | Q1: UX aspect | R1: Challenges | S1: Future work | T1: Reviewed by
A2: P29 | B2: Experiencing immersive virtual reality in museums | C2: Hyunae Lee; Timothy Hyungsoo Jung; M.Claudia tom Dieck; Namho Chung | D2: Smart Tourism Research Center, Kyung Hee University, Republic of Korea | E2: 2020 | F2: South Korea | G2: Science Direct | H2: Elsevier | I2: Jornal of Information and Management | J2: Journal | K2: 616 | L2: Virtual Reality (VR) has been regarded as a highly effective technology that enables people to gain enjoyable and immersive information about museum collections. Drawing from the four realms of the experience economy, we assume absorptive experiences influence immersive experiences, overall museum VR tour experience, and intention to visit a museum. The results show that all the hypotheses are supported. Furthermore, we compared and tested the proposed model and its rival model (postulating the direct influence of the four realms of the experience economy on museum VR experience) and found that the proposed model is better than the rival model. | M2: proposed a causal experience-economy model for museum VR to explain how immersive experiences translate into stronger museum-related outcomes. Using SEQ, the study shows that absorptive experience influences immersive experience, which in turn enhances the overall VR museum experience and increases intention to visit a museum. The proposed model is supported empirically and outperforms a rival model that posits direct impacts of the four realms of the experience economy on museum experiences. The findings suggest that VR museum design should emphasize edutainment factors to enhance visitor immersion and encourage onsite visitation. | N2: Cultural Heritage & Exhibition | O2: Geevor Tin Mine Museum | P2: 269 | Q2: education, entertaiment, estatics, and escapism | R2: limitations primarily revolve around the single-location data collection, the narrow scope of factors influencing immersion, and the specific cultural and technological context of the study. These limitations offer clear directions for future research to broaden the generalizability and depth of understanding regarding immersive VR experiences in cultural settings | S2: future studies could benefit by collecting data from various museums to provide more comprehensive and applicable results; further studies should include other factors of VR environments, enabling users to be immersed. | T2: A.Abdulhamid
A3: P4 | B3: Using Presence Questionnaires in Virtual Reality | C3: Valentin Schwind, Pascal Knierim, Nico Haas, Niels Henze | D3: University of StuttgartStuttgart, Germany | E3: 2019 | F3: Germany | G3: ACM DL | H3: ACM | I3: Proceedings of the 2019 CHI conference on human factors in computing systems | J3: Conference | K3: 551 | L3: Virtual Reality (VR) is gaining increasing importance in science, education, and entertainment. A fundamental characteristic of VR is creating presence, the experience of 'being' or 'acting', when physically situated in another place. Measuring presence is vital for VR research and development. It is typically repeatedly assessed through questionnaires completed after leaving a VR scene. Requiring participants to leave and re-enter the VR costs time and can cause disorientation. In this paper, we investigate the effect of completing presence questionnaires directly in VR. Thirty-six participants experienced two immersion levels and filled three standardized presence questionnaires in the real world or VR. We found no effect on the questionnaires' mean scores; however, we found that the variance of those measures significantly depends on the realism of the virtual scene and if the subjects had left the VR. The results indicate that, besides reducing a study's duration and reducing disorientation, completing questionnaires in VR does not change the measured presence but can increase the consistency of the variance. | M3: investigated the effects of completing presence questionnaires in VR, as opposed to the traditional method of having participants leave VR to complete them in the real world (). Based on mixed-design study conducted, the findings provide design implications and directions for optimizing presence questionnaires for use within VR, contributing to improved methodologies in VR research. | N3: Entertainment | O3: First-Person drone shooter game | P3: 36 | Q3: Presence, Workload | R3: while the study suggests that filling out presence questionnaires directly in VR can be beneficial by reducing study duration and disorientation, it highlights several limitations related to potential confounding variables, the nuanced nature of Break-in-Presence, the design and input methods of questionnaires, and the inherent reliance on memory in post-experience assessments. These limitations point to areas for future research to refine VR presence measurement. | S3: For future work, the authors recommend using a measure for immersion at the moment it is perceived, as questionnaires in VR can reduce score variance and avoid confusion after leaving the VR and removing the HMD | T3: A.Abdulhamid
A4: P50 | B4: Do VR and AR versions of an immersive cultural experience engender different user experiences | C4: Isabelle Verhulst; Andy Woods; Laryssa Whittaker; James Bennett; Polly Dalton | D4: Royal Holloway University of London (StoryFutures), United Kingdom | E4: 2021 | F4: United Kindom | G4: Web of Science | H4: Elsevier | I4: Journal of Computers in Human Behavior | J4: Journal | K4: 149 | L4: Although Virtual Reality (VR) and Augmented Reality (AR) user experiences have received large amounts of recent research interest, a direct comparison of different immersive technologies' user experiences has not often been conducted. This study compared user experiences of one VR and two AR versions of an immersive gallery experience ‘Virtual Veronese’, measuring multiple aspects of user experience, including enjoyment, presence, cognitive, emotional and behavioural engagement, using a between-subjects design, at the National Gallery in London, UK. Analysis of the self-reported survey data (N = 368) showed that enjoyment was high on all devices, with the Oculus Quest (VR) receiving higher mean scores than both AR devices, Magic Leap and Mira Prism. In relation to presence, the elements ‘spatial presence’, ‘involvement’, and ‘sense of being there’ received a higher mean score on the Oculus Quest than on both AR devices, and on ‘realism’ the Oculus Quest scored significantly higher than the Magic Leap. Cognitive engagement was similar between the three devices, with only ‘I knew what to do’ being rated higher for Quest than Mira Prism. Emotional engagement was similar between the devices. Behavioural engagement was high on all devices, with only ‘I would like to see more experiences like this’ being higher for Oculus Quest than Mira Prism. Negative effects including nausea were rarely reported. Differences in user experiences were likely partly driven by differences in immersion levels between the devices. | M4: directly compare UX between VR and AR versions within a real-world cultural institution setting, aimed to understanding how VR and AR versions affect user perceptions of presence, engagement, enjoyment, and whether they induce negative side effects. The study conduct user study involving 368 perticepant, utilizing immersive gallery experience called 'Virtual Veronese' offered in one VR version and two AR versions. The findings indicate that enjoyment and presence were significantly higher in the Oculus Quest compared to AR devices, suggesting that variations in immersion levels between devices may influence UX. | N4: Cultural Heritage & Exhibition | O4: Immersive strory telling | P4: 368 | Q4: enjoyment, presence, cognitive, emotional and behavioural engagement | R4: while the study provides valuable insights into user experiences with VR and AR in a cultural setting, its generalizability is somewhat constrained by the specific demographic of participants.; Another limitation relates to the duration of the experience and the low number of reported negative effects. The experience lasted for only 6 min, and it is possible that more negative effects (such as fatigue and feeling uncomfortable) could have been reported if the intervention had lasted longer. Future studies could build upon these findings by addressing these limitations and exploring the role of environmental context and longitudinal user experience data. | S4: Future research can look into the importance of the Gallery setting on user experience, and to what extent the VR user experience is influ_x0002_enced by the physical presence of the (unseen in VR) physical painting; In addition, since data were collected immediately after the experience, future research could cover additional time points, for example pre-experience (user expec_x0002_tations), and user experiences during, immediately after the experience and longer term | T4: M.B Umar
A5: P12 | B5: A Physiology-Based QoE Comparison of Interactive Augmented Reality, Virtual Reality and Tablet-Based Applications | C5: Conor Keighrey; Ronan Flynn; Siobhan Murray; Niall Murray | D5: Institute of Technology, Athlone, Ireland | E5: 2021 | F5: Ireland | G5: IEEE Xplore | H5: IEEE | I5: IEEE Transactions on Multimedia Journal | J5: Journal | K5: 76 | L5: The availability of affordable head-mounted display technology has facilitated new, potentially more immersive, interactive multimedia experiences. These technologies were traditionally focused on entertainment; however, academia and industry are now exploring applications in other domains such as health, learning and training. Key to the success of these new multimedia experiences is the understanding of a user's perceived quality of experience (QoE). Subjective user ratings have been the primary mechanism to capture insights into a user's experience. Such ratings have generally been captured post experience and reflected using a mean opinion score (MOS). However, user perception is multifactorial and subjective ratings alone do not express the true measure of an experience. As a result, recent efforts to capture QoE have included exploring the use of implicit metrics (e.g., physiological measures). This article presents the results of an experimental QoE evaluation and comparison of immersive applications delivered across three multimedia platforms. The platforms compared were augmented reality, tablet and virtual reality. The QoE methodology employed considered explicit (post-test questionnaire) and implicit (heart rate and electrodermal activity) assessment methods. The results indicate comparatively higher levels of QoE for users of the augmented reality and tablet platforms. | M5: compare the QoE of immersive applications delivered across three multimedia platforms (AR, VR, and tablet). It highlights the differences in UX among these technologies, contributing to the understanding of their effectiveness. Explicit and implicit measures show that AR and tablet technologies provide higher QoE compared to VR, suggesting their potential for effective speech and language assessment. | N5: Multimedia | O5: immersive speech & language therapy application | P5: 60 | Q5: Enjoyment, Immersion, interaction and discomfort | R5: Although the implicit capture of EDA reveals an increase in physiological arousal for the VR group, this may be attributed to limitations associated with the technology. For instance, unlike the VR hardware, both the AR and tablet environments support native gesture controls. In addition, the display technology differs between each of the immersive multimedia devices | S5: Future work will further explore the utility of EDA as a measure of cognitive load or stress within the context of a virtual assessment. In particular, the work will integrate and evaluate the utility of already established measures of cognitive activity, such as pupillary response. | T5: M.B Umar
A6: P39 | B6: Immersive virtual reality news: A study of user experience and media effects | C6: Huiyue Wu; Tong Cai; Dan Luo; Yingxin Liu; Zhian Zhang | D6: The School of Communication and Design, Sun Yat-sen University, Guangzhou, China | E6: 2021 | F6: China | G6: Scopus | H6: Elsevier | I6: International Journal of Human-Computer Studies | J6: Journal | K6: 73 | L6: Recently, the concept of “immersive VR news” has been proposed in the news media field. However, unlike traditional video news, the user experience and media effects of immersive VR news have yet to be verified. To examine the influence of VR technology on the news media field, we designed an immersive VR news product to further discern differences in user experience and media effects among traditional video news, VR news without interaction, and VR news with interaction. The results show that traditional video news excelled in terms of empathy and nervousness, whereas VR news with interaction was superior in terms of immersion, interest, accuracy, and credibility. VR news without interaction performed the poorest in all categories. Based on the observed user behaviors during the experiment, we present a detailed discussion of the reasons for these dif_x0002_ferences and offer guidelines for the design and application of immersive VR news. | M6: investigate the UX and media effects of immersive VR news between traditional video news, VR news without interaction, and VR news with interaction. They develop an Immersive VR news that presents events from a first-person perspective and conducts empirical study. The findings highlight the added value of interactivity in VR news and provide design guidelines to improve the effectiveness of immersive journalism. | N6: Multimedia | O6: immersive VR news. | P6: 131 | Q6: immersion, Empathy, Accuracy, Emotion, Credibility | R6: while this study provides valuable insights into immersive VR news, its limitations highlight the need for broader application, larger sample sizes, long-term impact studies, and more refined measurement techniques to enhance the robustness and generalizability of future findings | S6: more research is needed with a good control over factors such as the visual fidelity and aesthetic appeal of the actual news content to obtain a deeper understanding of the usability and fidelity issues; and test immersive VR applications across diverse news types and contexts to validate findings across content genres; use validated instruments (e.g., IPQ, PQ, ITC-SOPI) to capture subjective immersion and sense of presence. | T6: A.Abdulhamid
A7: P51 | B7: How do users experience the interaction with an immersive screen? | C7: Shin Donghee; | D7: College of Communication and Media Sciences, Zayed University, PO Box 144534 Abu Dhabi, UAE | E7: 2019 | F7: United Arab Emirate | G7: Web of Science | H7: Elsevier | I7: Journal of Computers in Human Behavior | J7: Journal | K7: 68 | L7: Ultra-high definition television (UHDTV) is designed using a variety of immersive technologies that are believed to promote user engagement. This study examines the immersion feature of UHDTV by focusing on user experience (UX) to determine whether there is a favorable response by users and whether immersion improves their viewing experience. Further, it examines the relationship between UX and the quality perception of UHDTV to develop a conceptual model for users' quality of experience (QoE) with respect to UHDTV. It uses multiple methods combining experiment (to measure the effect of the immersive experience) and survey (to model the UHDTV UX). The results imply an optimum level of immersion as well as the need for user-based quality measurement. The results confirm the existing models of predicting user intentions with digital technologies and have potential to provide new insights to the research of immersive technologies. | M7: proposed a conceptual QoE model for Ultra-High-Definition Television (UHDTV) by linking UX to perceived quality and examining how user interactions with immersive UHDTV features shapes viewing experience. Using a mixed-method approach that combines experiment and survey, the findings confirm that greater technical immersion does not necessarily yield higher satisfaction or QoE. Instead, user-centric factors, particularly cognitive confirmation and individual perception, play a more significant role in determining immersion and overall QoE. | N7: Multimedia | O7: Immesive UHDTV | P7: 120 | Q7: hedonicity, utility, Immersion, Flow, Presence, Expectation, Confirmation, Satisfaction, intention | R7: limitations primarily revolve around the representativeness and generalizability of its sample, the need for a more comprehensive QoE framework that includes emotional and external factors, and the importance of considering varied technical and viewing conditions in future research | S7: Future studies carefully consider the generalizability of findings and the applicability to the broader research community; Finally, while this study proposes a QoE framework, there is room for further clarifications and refinement. Future studies can focus on developing a new evaluation framework based on users' emotional aspects. Beyond simply measuring colors, resolution, and picture quality in UHDTV, the new emotional frameworks call for measuring all technical features and carefully considering external factors such as external contextual factors as well as users' emotional factors | T7: A.Abdulhamid
A8: P21 | B8: The Introduction of a Novel Virtual Reality Training System for Gynecology Learning and Its User Experience Research | C8: CHEN-WEI CHANG; SHIH-CHING YEH; MENGTONG LI; EASON YAO | D8: School of Journalism, Fudan University, Shanghai 200433, China | E8: 2019 | F8: China | G8: IEEE Xplore | H8: IEEE | I8: IEEE Access Journal | J8: Journal | K8: 63 | L8: The researchers of this study designed a new virtual reality (VR)-assisted training system, IFOREAL, for gynecology students at their university and introduced it to potential trainees. Two versions of IFOREAL, each employing different devices, were developed. The consumer version uses a traditional LCD display and computer mouse, whereas the professional version utilizes a head-mounted display (HMD) and joystick controller for the virtual learning. Trainees watched simulated videos and interacted with the system to accomplish tasks. IFOREAL consists of several major learning modules of gynecology. This study used the normal spontaneous delivery module to research user experience and perceptions of the IFOREAL VR training system. The results suggested that most of the trainees' user experiences and perceptions of IFOREAL, using both the types of VR-assisted technology, were positively reported. Trainees who used the consumer version of IFOREAL perceived a stronger internal control, whereas trainees using the professional version perceived a better sense of virtual presence. Overall, trainees perceived the usefulness of the IFOREAL system which predicted their future intention to use the system and other similar VR-assisted training systems for learning. Furthermore, whether the virtual content of IFOREAL grabbed the trainees' attention predicted their future intenon to use professional devices of HMD/joysck for learning other subjects. The gender difference was also explored in the study. Generally speaking, female trainees gave better evaluations of IFOREAL compared to their male counterparts. They perceived a better internal control while using the consumer version than the professional version. Male trainees believed that the gadgets used in the professional version provided a better virtual presence and met their expectation of a virtual experience better. This study suggested that different versions of IFOREAL could serve trainees' different needs. Technology developers and trainers should tailor the application of different VR devices to assist with the training/learning in accordance with different conditions/trainees | M8: introduces IFOREAL, a VR-based childbirth simulation designed to train gynecology students. The authors evaluate students’ acceptance and intention to use VR for learning across two interaction setups (desktop and HMD). The findings provide practical guidance on effectively integrating VR into education and training, particularly in medical field. | N8: Healthcare | O8: IFOREAL VR system | P8: 87 | Q8: perceived usefulness, Ease of use, enjoyment, Behaviour control, internal control, attitude, satisfaction, confirmation, engagement, attention, presence, intention to use the system | R8: The interpretation of results based on questionnaire data might tell only part of the story, as it could be biased due to the nature of self-reports | S8: future studies could apply different research methods to gauge trainees’ user experience, such as a psychophysiological approach, which could provide empirical evidences other than the self-reporting data; researchers could further develop the system using haptic devices for practices such as palpation, which could possibly provide learners with an advanced virtual experience for gynecology training | T8: M.B Umar
A9: P44 | B9: Evaluating the user interface and experience of VR in the electronic commerce environment: a hybrid approach | C9: Kuo‑Wei Su; Shih‑Chih Chen; Po‑Hung Lin; Ching‑I Hsieh | D9: National Kaohsiung University of Science and Technology Taiwan | E9: 2020 | F9: Taiwan | G9: Scopus | H9: Springer Nature Link | I9: MDPI Journal of Virtual Reality | J9: Journal | K9: 62 | L9: In recent years, to attract global manufacturers, media reporters, and consumer attention, a popular term in search engines has been virtual reality (VR). In addition to video, entertainment, education, and medical, VR can be used in electronic commerce (E-commerce). Currently, most E-commerce platforms present products using 2D images, text-based interface or animation. However, consumers want to know more about the products while online shopping and compare the product’s material, color, and other elements. Therefore, combining VR with E-commerce can improve the user’s shopping experience. This study will focus on the characteristics of VR and E-commerce. This feature can be used to interactively study UI and UX between users and designers to generate design criteria. Experimental design is carried out through the modified SEM-CPU method. Then, we use the think-aloud protocols, Questionnaire for User Interaction Satisfaction, and User Experience Questionnaire to understand the user’s thoughts on UI and UX. Moreover, this study uses focus group to interview experts to obtain expert opinions on VR E-commerce. Induction and integration of data is carried out to produce design criteria by experimental results. Finally, the Delphi method is utilized to validate and evaluate the practicability of the design criterion. Through the “UI and UX design criteria of VR” generated by this study, many important design elements can be proposed and assessed in VR E-commerce. In closing, this study provides design and development suggestions for VR developers to improve the positive influence of UX. | M9: proposes ‘UI and UX design criteria of VR' for e-commerce, covering themes like screen, operation, safety, system functions, and transaction. It provides design and development suggestions for VR developers to improve UX in e-commerce. The study underscores the need for more academic work on VR in e-commerce and offers practical reference for industry practitioners. | N9: Retail & Marketing | O9: VR E-commerce | P9: 30 | Q9: screen, operation and prompt, safety and experience of use, system functions, and transaction | R9: The study focuses on the furniture area, limiting broader applicability; In-depth discussions on specific fields are recommended for future research; The research may not fully apply to other VR applications | S9: future research, could explore specific areas so they can be better understood and achieve better research results.; Future research may explore diverse uses of gestures, voice operations, and infrared sensing to develop more user-centric interfaces and services; | T9: A.Abdulhamid
A10: P49 | B10: Exploring User Experience and Usability in a Metaverse Learning Environment for Students: A Usability Study of the Artificial Intelligence, Innovation, and Society (AIIS) | C10: Aung Pyae; Werner Ravyse; Mika Luimula; Emiliana Pizarro-Lucas; Pedro L. Sanchez; Ignacio P. Dorado-Diaz; Aung Khant Thaw | D10: International School of Engineering, Faculty of Engineering, Chulalongkorn University, Bangkok 10330, Thailand | E10: 2023 | F10: Thailand | G10: Scopus | H10: MDPI | I10: MDPI Journal of Electronics | J10: Journal | K10: 62 | L10: The metaverse, a rapidly evolving research area, is a virtual, interconnected universe that seamlessly integrates digital and physical realms, facilitating immersive experiences, social interaction, and economic activities across various fields, including computer science, business, and education. Despite its potential to transform current pedagogies and learning experiences through engaging, interactive, and fascinating educational techniques, research is limited in exploring its application, usability, and user experience, particularly for Thai undergraduate students in learning computer engineering courses. In response, we designed and developed an innovative metaverse-based learning system called the AIIS collaborative learning interface, tailored to European undergraduate students. While the original intent of AIIS was to cater to medical students, in this study, our objective was to assess its usability and applicability for computer science and engineering students, specifically focusing on the Asian demographic. After an initial pilot with European students in their local context, the research was extended to Thailand, where 21 Thai undergraduate students evaluated the platform’s usability. The observations from this study indicate that AIIS provides a dynamic, user-friendly learning environment. Nevertheless, the evaluation process unveiled some usability flaws that offer informative directions for future enhancements. Drawing from our observations, we formulated usability guidelines to guide designers and developers toward crafting more efficient metaverse systems, particularly those intended for educational use. Our results also underline the considerable promise that metaverse technologies hold for advancing higher education globally. | M10: conduct a mixed-method usability and UX evaluation of the “AIIS system”, a metaverse-based learning environment that integrates digital and physical experiences while supporting social interaction and economic activities. The results indicate positive usability outcomes and suggest that metaverse learning platforms may enhance higher-education experiences and support new approaches beyond conventional teaching methods. | N10: Education & Training | O10: AIIS system | P10: 21 | Q10: Competence, Immersion, Flow, Tension, Challenge, Negative affect, Positive affect | R10: Limitations such as a constricted sample size, the concise duration of testing, demographic specificity, and the non-usage of immersive head-mounted displays during trials do cast certain shadows. These caveats accentuate the necessity for continued exploration and provide a roadmap for future investigations. (limitations highlight the need for continued exploration with broader participant demographics, longer study durations, and the inclusion of advanced immersive technologies to enhance the robustness of future conclusions and further refine metaverse-driven pedagogy) | S10: Future research should explore the barriers to the adoption of VR/AR/XR technologies and the metaverse, aiming to identify strategies that encourage more regular engagement with these innovative technologies; Researchers are encouraged to investigate the usability flaws identified during the evaluation process to guide the development of more efficient metaverse systems for educational use | T10: M.B Umar
A11: P34 | B11: The evaluation of user experience of a human walking and a driving simulation in the virtual reality | C11: Ilsun Rhiu; Yong Min Kim; Wonjoon Kim; Myung Hwan Yun | D11: Division of Future Convergence, Dongduk Women’s University, Seoul, 02748, Republic of Korea | E11: 2020 | F11: South Korea | G11: Science Direct | H11: Elsevier | I11: International Journal of Industrial Ergonomics | J11: Journal | K11: 56 | L11: Virtual reality (VR) has been implemented in various applications such as gaming, e-learning, rehabilitation, etc. Although many studies have been conducted to evaluate the user experiences (UX) of various applications in VR, there are few studies evaluating the UX of VR in a holistic view. Since user experience means holistic feelings caused by attributes like efficiency, effectiveness, pleasure, and attractiveness, it is necessary to evaluate user experience in many respects, including presence, usability, and workload. Therefore, this study aims to evaluate the UX of VR in four various metrics: presence, workload, usability, and flow. In this study, the user experience factor was confirmed through the previous studies comparing visual display terminals (VDT) and head-mounted displays (HMD). In addition, the UX difference between VDT and HMD in two different situations, walking and driving, is analyzed. The data of 26 participants were analyzed and found that there were significant differences in the four studied metrics related to UX. In the driving situation, the usability value was higher in VDT, whereas they were higher in HMD for walking. Comparing the two contexts in HMD, walking was significantly higher in three metrics: presence, usability, and flow. The results show that HMD is better in terms of user experience than VDT, and HMD is more suitable for walking situations than for driving situations. Through this study, in terms of user experience, it is suitable to replace walking tasks with VR when the experiment in a real-world environment is impossible. | M11: compare Visual Display Terminals (VDTs) and HMDs in walking and driving simulations to examine how device type and scenarios influence UX. The results indicate that HMDs enhance UX more effectively than VDTs, particularly in walking tasks, underscoring the need to account for context-specific UX differences when designing VR systems. | N11: Entertainment | O11: City Car Driving and Pollen | P11: 26 | Q11: presence, workload, usability, and flow. | R11: To fully understand the quantitative differences in UX, future research should involve collecting physiological signals and comparing them with qualitative survey data. Additionally, there is a need for further studies to improve the performance of each UX indicator for specific devices, such as enhancing mental fatigue and inconvenience for HMDs or improving sound and visual effects for VDTs to boost presence . The study also suggests investigating the differences between real-world environments and HMDs for various situations | S11: future UX studies that segment tasks and contexts, include more diverse samples to probe gender and experience effects, enhance HMD and VDT designs (reducing fatigue and improving presence), and compare VR with real environments using combined physiological and self-report measures | T11: M.B Umar
A12: P40 | B12: The sense of being there during online classes: analysis of usability and presence in web-conferencing systems and virtual reality social platforms | C12: Manuela Chessa; Fabio Solari | D12: Department of Informatics, Bioengineering, Robotics, and Systems Engineering, University of Genoa, Genova, Italy | E12: 2021 | F12: Italy | G12: Scopus | H12: Taylor & Francis | I12: Journal of Behaviour & Information Technology | J12: Journal | K12: 53 | L12: Due to the Covid-19 pandemic, millions of people had to stay at home for several months and to move their everyday activities online. From smart-working to online learning, also considering entertainment activities, people started to extensively use platforms for remote communication and for sharing video, text, and audio content. Such systems are able to cope with the need of communicating, but the common feeling is that people, and especially students, are missing the physical relationships with classmates and colleagues. In this paper, we analyse two modalities that can be used to give an online University lecture, by focusing on the ‘sense of presence’, i.e. on the ability to produce into students the psychological sense of being in a classroom together with the teacher and their classmates. We consider a standard web-conferencing system, and a Virtual Reality social platform. We also take into account the ‘usability’ factors, to understand if extended reality systems could be, in a near future, a possible alternative to improve distance lectures and meetings. | M12: analyzes two modalities for delivering online university lectures, focusing on the 'sense of presence' to enhance the learning experience during remote education due to the Covid-19 pandemic. The study compares a standard web conferencing system with a Virtual Reality social platform, assessing usability factors to explore potential improvements in distance learning. The findings highlights the importance of immersive VR in enhancing interactive lectures, despite current limitations in student interaction on platforms like Mozilla Hubs. The study proposes future developments, such as integrating tools for virtual laboratories, to further enhance educational experience. | N12: Education & Training | O12: VR social platform (Mozilla Hubs) | P12: 30 | Q12: presence, realism, involvement, usability,; User experience aspect from UEQ | R12: its limitations, particularly regarding the non-immersive VR setup and the participants' unfamiliarity with VR technology, suggest that the observed usability challenges might be overcome with improved technology access and user training. | S12: Future research could explore the integration of VR headsets to enhance the 'sense of being there', as preliminary results indicate potential benefits despite usability issues; Investigating the impact of immersive VR on learning outcomes is suggested, particularly comparing it to traditional desktop environments; | T12: A.Abdulhamid
A13: P31 | B13: An empirical study on user experience evaluation of VR interface in digital museums | C13: Xi Pei; Shiting Fu; Tingting Jiang | D13: School of Imformation Management, Wuhan University, Wuhan, Hubei, China | E13: 2023 | F13: China | G13: Science Direct | H13: Elsevier | I13: Journal of Data and Information Management | J13: Journal | K13: 46 | L13: Virtual reality (VR) has been increasingly introduced to digital museums to enable more immersive experiences. However, there is a lack of comprehensive evaluation for user experience in VR-based digital museums. A comprehensive framework for evaluating user experience of VR interfaces in digital museums was created. Based on this framework, the study conducted an experiment to investigate learning effectiveness in VR-based digital museums and compared user experience on desktop and mobile devices. A total of 45 participants were recruited. They were asked to visit a digital museum on either a desktop or a mobile device. After they completed their visit, they took a recognition test and a recall test to measure their effectiveness of learning. Their user experience was evaluated using a new scale, followed by an open-ended interview to collect their opinions and feedback. It was found that introducing VR to the digital museum helped increase users’ effectiveness of learning. Significant differences existed between the desktop and mobile VR interfaces in user experience. It means that previous research findings cannot be directly applied to the user experience of digital museums on mobile. These empirical evidences also suggest that the established framework is effective for evaluating the user experience in VR-based digital museums. | M13: developed comprehensive framework for evaluating UX in VR-based digital museums grounded in Cultural User Experience (CUX) theory, covering both pragmatic and hedonic aspects. The study also investigates learning effectiveness of VR interface across device types (desktop and mobile). Experiment results demonstrate that VR technology enhances immersion and knowledge learning, contributing to a better educational experience in digital museums. | N13: Cultural Heritage & Exhibition | O13: VR Panorama Palace Museum | P13: 45 | Q13: users’ perceptions, system usability, and effectiveness of learning, attitude, and intention. | R13: main limitations revolve around the narrow demographic of participants and the reliance on subjective self-report measures, suggesting a need for broader participant inclusion and more objective measurement techniques in future work | S13: Digital museums are universal, so children, Digital museums are popular and universal, so children, middle-aged people and the elderly could be considered in the future.; In the future, physiological indicators could be considered in order to increase the generalizability of the findings | T13: A.Abdulhamid
... A33: P22 | B33: Holistic User eXperience in Mobile Augmented Reality Using User eXperience Measurement Index | C33: Fahad Ahmed Satti; Jamil Hussain; Hafiz Syed Muhammad Bilal; Wajahat Ali Khan; Asad Masood Khattak; Ju Eun Yeon; Sungyoung Lee | D33: Computer Engineering KyungHee University South Korea | E33: 2019 | F33: South Korea | G33: IEEE Xplore | H33: IEEE | I33: Conference on Next Generation Computing Applications (NextComp) | J33: Conference | K33: 12 | L33: User eXperience (UX) evaluation in the field of Mobile Augmented Reality (MAR) is a challenging task, which requires the application of many heterogeneous methods, producing a variety of raw signals and subjective data. This multi-method approach is essential for capturing the holistic UX of any product, service or system. In order to convert this data into information and subsequently knowledge, a comprehensive and scalable system is required which can not only quantify the individual UX metrics but also produce a concise result, which is interpretable by anyone. We call this result, the User Experience Measurement Index, and in this paper we present the results of adopting the mixed method UX evaluation approach for evaluating a prototype MAR application using various methods and sensors, applied before, during, and after its usage. Additionally, we present the methodology and results for calculating the UXMI. | M33: proposes mixed-method UX evaluation approach for MAR, which captures a holistic UX through various methods and sensors on different usage stages. In addition, the study introduces a User Experience Measurement Index (UXMI) that quantifies individual UX metrics and produces interpretable results. Based on experiments in real MAR implementation. The findings suggest that a mixed method approach can enrich UX results, bridging gaps between subjective assessments and empirical data. | N33: Entertainment | O33: MAR Madness | P33: 9 | Q33: Perception of instrumental qualities; non-instrumental quality and emotional resposes | R33: while the paper introduces a valuable multi-method UX evaluation approach and the UXMI, it acknowledges that the limited number of participants, the simplified testing context, and a potential sensor inaccuracy are factors that might influence the generalizability and completeness of its findings. | S33: Apply and validate the UXMI-based mixed-method UX framework with larger and more diverse user groups and across different interactive systems to confirm generalizability and support long-term MAR UX evaluation | T33: M.B Umar
A34: P10 | B34: Design and development approach for an interactive virtual museum with haptic glove technology | C34: Emma, EF, Fallows; David, DW, White; Neil, NJB, Brownsword | E34: 2022 | F34: United Kindom | G34: ACM DL | H34: ACM | I34: Proceedings of the 25th international academic mindtrek conference | J34: Conference | K34: 11 | L34: With a rise in the use Virtual Reality (VR) applications in museums and exhibition displays, digital heritage has still shown limitations in what a visitor can experience from the intersection of technology and history. Traditionally, interpretative narrative within the museum has been communicated through text panels offering limited context from a largely connoisseurly perspective. In addition to these interactive digital resources are often data base orientated via touch screen technologies with no multisensory immersion. This paper addresses the digital changes in these educational landscapes and the way it is being handled to co-create digital tools for exhibitions to educate and entertain museum visitors. This paper explores the use of haptic technology in conjunction with virtual reality to facilitate multi-faceted modes of interpretation, that offer novel access to an artefact's history from a range of perspectives. It also provides evidence of increased visitor engagement with a ceramic display through these immersive methods to communicate a narrative. This research bridges the gap between history and technology to offer an immersive experience of visiting a museum virtually and providing an intimate one-one experience to interact with artefacts and learn about history. As its focus, this research digitally reconstructs a collection of East-Asian ceramics bequeathed by Ernest Thornhill in 1944 to North Staffordshire Technical College (Now known as Staffordshire University). The digital prototype was developed to replicate the museum environment without the restrictions to access artefacts and handle them. This experience offers visual insights to contextualise the history of a ceramic to be utlised as an education tool to enhance learning within a museum setting. Evidence showed a significantly positive response to this prototype in museum and gallery settings, responses revealed these methods of interaction did assist in learning about ceramics, with a distinct majority of participants confirming these installations would encourage future visits, shaping the possibilities of how history can be combined with technology to create new and innovative solutions to learn about an artefact | M34: present a design and development approach for an interactive virtual museum that integrates haptic glove technology within VR to enhance visitor engagement and learning. Their experimental results demonstrated that the integration of haptic technology with virtual reality significantly enhances visitor engagement and interaction with museum artefacts, providing a more immersive experience than traditional methods. | N34: Cultural Heritage & Exhibition | O34: Thornhill Museum Experience | P34: 59 | Q34: screen factors, terminology, and system feedback, learning factors and system capabilities, user satisfaction | R34: while the interactive virtual museum with haptic glove technology offers significant advancements in visitor engagement and learning, it still encounters challenges related to the realism of haptic feedback, the high cost of the technology, and the inherent limitations of virtual interaction compared to physical handling. These factors impact the full extent of sensory immersion and interpretation that can be achieved | S34: improving haptic technology, reusing the workflow with other artefacts and museums, and expanding digital heritage applications to justify investment and bring such VR experiences into mainstream exhibitions | T34: A.Abdulhamid
A35: P32 | B35: From knowledge to action: Assessing the effectiveness of immersive virtual reality training on safety behaviors in confined spaces using the Kirkpatrick model | C35: Alessandro Evangelista; Vito M. Manghisi; Vito De Giglio; Raffaele Mariconte; Claudia Giliberti; Antonio E. Uva | D35: Polytechnic University of Bari, Via Edoardo Orabona, 4, 70126 Bari, Italy | E35: 2025 | F35: Italy | G35: Science Direct | H35: Elsevier | I35: Journal of Safety Science | J35: Journal | K35: 11 | L35: Safety in the industrial sector is paramount, with national legislations establishing specific regulations to reduce accidents. These regulations emphasize risk removal and proper operator training as preventive measures. However, traditional training can be time-consuming and costly, leading companies to meet only the minimum requirements. In particular, confined spaces pose significant dangers, often resulting in fatal, cascading accidents due to a lack of proper safety procedures. Therefore, effective training is crucial to mitigate these risks. Advanced technologies like Immersive Virtual Reality (IVR) present new opportunities for cost-effective and extensive training campaigns by eliminating the risks associated with real environment training, offering a safe yet realistic experience. Despite the widespread adoption of IVR training applications in industrial research, there is a notable lack of systematic approaches to evaluate their effectiveness. Conducting such evaluations is crucial to ascertain their impact on essential training outcomes, including participant engagement, knowledge transfer, and enhanced safety behavior during work activities. To address this gap, we developed an IVR-based training platform for confined space safety procedures and established a systematic validation procedure using the Kirkpatrick model to assess its effectiveness compared to conventional training methods. Results demonstrate that IVR training provides an excellent user experience, better knowledge transfer than the traditional approach, and improved performance in simulated procedures, reducing execution errors and completion times. This dual focus on creating and validating the IVR system underscores its potential as an effective training tool in hazardous environments such as confined spaces, where proper training can prevent tragic fatalities. | M35: develop and evaluate an Immersive VR (IVR) training module for confined space scenarios. Using a validation procedure based on the Kirkpatrick model, the platform supports both training and testing modes, enabling users to practice and assess their knowledge in realistic virtual environments. The experiment results indicate that the IVR training can improve safety procedures and performance in confined-space operations, highlighting its practical impact on workplace safety. | N35: Education & Training | O35: VR room-scale (Copine Space) | P35: 50 | Q35: pragmatic and hedonic quality; perceived usability; Simulation Scikness | R35: sample size is modest and not gender-balanced, which limits generalisability.; The study did not evaluate long-term outcomes such as accident reduction or productivity in real confined spaces; transfer of skills from IVR to real CS environments is therefore not yet confirmed. (while the study provides strong evidence for the benefits of IVR training in confined spaces, particularly in user experience and behavioral improvement, its findings are constrained by the sample's demographics, size, and the short-term focus of the evaluation. Future research should aim to address these limitations through larger, more diverse cohorts and long-term, real-world validation studies.) | S35: additional validation step is required to assess its consistency with the results obtained from such evaluations. (Conduct follow-up studies comparing IVR-trained workers’ performance and safety outcomes in actual CS operations to confirm transfer of learning and behavior); Increase sample size and include female participants and other worker profiles to improve statistical power and generalisability | T35: A.Abdulhamid
A36: P45 | B36: Education in the metaverse: Developing virtual reality teaching materials for K–12 natural science | C36: Cheng‑Hung Wang | D36: National University of Kaohsiung (NUK) | E36: 2025 | F36: Taiwan | G36: Scopus | H36: Springer Nature Link | I36: Springer Journal of Education and Information Technologies | J36: Journal | K36: 9 | L36: In the post-COVID-19 era, information education with highly interactive teaching methods has become increasingly common. In particular, the metaverse and virtual reality (VR) technology can be used in novel learning methods to leverage the intuitiveness, immersivity, and interactivity of VR. For example, students could use VR to simulate scientific experiments in chemistry, biology, or physics that would require handling dangerous chemicals or biological samples, mitigating real-world experimental risks. This study investigated the effective use of emerging technologies in K–12 education through the development of a VR teaching material “Escape from the Material Room” for junior high school students with the goals of cultivating students’ core competencies in self-directed learning and enhance the learning experience. The development process involved two stages: first, 45 university students participated in a preliminary usability assessment, providing feedback that led to minor interface adjustments. Subsequently, 25 junior high school students engaged with the optimized VR material as a supplementary course. Through detailed analysis of system usability, user satisfaction, and learning behavior, the study found that the key factors enhancing the effectiveness of VR teaching materials include interaction design, the intuitiveness of the user interfaces, and the integration of teaching content with learning objectives. The findings highlight the potential of VR to promote educational innovation and enhance the learning experience. By incorporating VR’s unique features, such as immersion and interactivity, into teaching and learning, educators can create more engaging and effective learning environments | M36: developed a VR teaching module "Escape from the Material Room," to support self-directed learning among junior high school students. The study evaluates its usability and user satisfaction to assess the suitability of emerging technologies in K-12 education. Findings underscore VR's potential to drive educational innovation and improve learning experiences by leveraging its immersive and interactive features. | N36: Education & Training | O36: educational VR program | P36: 70 | Q36: Ease of use, user satisfaction, and learning behaviour | R36: The study is limited by technical performance issues (e.g., interaction lag and unclear operations), insufficient in-game guidance for students, and a narrow scope focused on a single physics topic with a relatively small learner sample | S36: improvements in user guidance, interaction design, and the integration of mandatory experimental steps are necessary to optimize learning outcomes and user experience, especially for first-time users. These improvements aim to create a more natural and intuitive learning environment within VR. | T36: A.Abdulhamid
A37: P3 | B37: Using Redirection to Create a Swimming Experience in VR for the Sitting Position | C37: Chenyang Cai, Jian He,Tianren Luo | D37: Faculty of Information Technology, Beijing University of Technology Beijing, China | E37: 2023 | F37: China | G37: ACM DL | H37: ACM | I37: Companion Proceedings of the 28th International Conference on Intelligent User Interfaces | J37: Conference | K37: 8 | L37: As a primary locomotion method for some VR applications (e.g. diving, physical exercise, etc.), swimming creates an immersive and entertaining experience. Existing VR swimming methods often use complex and expensive setups to fix users in the mid-air to restore prone positions. While these methods provide realistic experiences, the hanging postures place an additional burden on the users and make them difficult to freely switch between the two swimming positions (prone and supine). Using redirection technology, we propose a new, easy, and effective method to simulate swimming in a comfortable sitting position. For visual simulation, this method redirects the -30° to 30° torso tilt range of the pitch axis in a sitting position to -90° to 90° through a rotation gain to the user’s view. For vestibular and proprioceptive simulation, we use the swimming action, the torso forward/backward leaning for swimming postures’ (backstroke and breaststroke) switching, the pillow and seat back for simulating the buoyancy of water. Preliminary experimental results show that our swimming method can create a good swimming experience for seated users. | M37: proposes a novel method for simulating swimming while seated, addressing the limitations of existing complex and expensive setups. The method incorporates natural multi-sensory stimuli to create realistic swimming experience. Preliminary user experiments results indicate that this approach leads to good swimming feelings and immersion with minimal learning costs. | N37: Entertainment | O37: VR Swimming System | P37: 10 | Q37: Feelings, immersion, tiredness, motion sickness, difficulty and enjoyment | R37: while the redirection method for VR swimming offers a novel and accessible approach, it faces challenges related to user comfort (physical exertion and motion sickness) and has a relatively narrow scope of validated application with a limited user study demographic | S37: A future study would build on this swimming method to develop more practical applications for swimming sports, exploring the ocean and many other aspects.; and evaluate UX from both objective and subjective data measures | T37: A.Abdulhamid
A38: P14 | B38: An Event-based User Experience Evaluation Method for Virtual Reality Applications | C38: Che Xiaoping, Siqi Ma, Qi Yu, and Chenfeng Yue | D38: School of Software Engineering, Beijing Jiaotong University, Beijing, China | E38: 2019 | F38: China | G38: IEEE Xplore | H38: IEEE | I38: IEEE SmartWorld, Ubiquitous Intelligence & Computing, Advanced & Trusted Computing, Scalable Computing & Communications, Cloud & Big Data Computing, Internet of People and Smart City Innovation | J38: Conference | K38: 7 | L38: With the development and advancement of Virtual Reality (VR) technology in recent years, hardware is no longer the main factor limiting VR into the public life, and the demand for user experience (UX) continues to increase. The development of VR is beginning to reveal a content-oriented trend. Whether the content is attractive enough will greatly affects users’ experience and determine the service life of VR applications. Consequently, searching for interaction events that would affect VR UX is critical to improve user stickiness. At present, the researches on VR mainly focus on the improvement of hardware and software, and pay less attention to the content event design. Moreover, there is no unified and clear standard for VR UX evaluation. This paper attempts to find out the relationship between user traits, VR interaction events and user experience through realistic experiments. This paper firstly define four types of VR interaction events, and design a questionnaire for collecting the tester’s traits and their subjective evaluation. During the experiment, objective physiological data of the testers and their participation process were recorded. The 80 testers were divided into two groups to experience two types of VR games with constant time. The statistical method and improved Prism algorithm were used to find out the correlation among user traits, type of game interaction events and user experience. The experiment results could provide references for VR designers and developers, and at the same time provide the preliminary study to standardized VR user experience evaluation | M38: introduces a comprehensive method for evaluating UX in VR, by combining subjective questionnaires with objective physiological data and an improved algorithm in realistic experiment. The findings provide insights into how user traits and interaction events influence VR experience, offering a foundation for optimizing VR content design and establishing standardized evaluation metrics. | N38: Entertainment | O38: The Lab VR game | P38: 80 | Q38: overall positive/negative/neutral experience | R38: The existing VR UX research on interaction is deemed insufficient, suggesting that the four defined interaction events (Touch, Grab, Operation, Move) might not cover the full spectrum of relevant interactions in VR, or that their impact needs further exploration; The study's findings are based on experiments with a limited number of samples (80 testers) and two specific VR games ('Slingshot' and 'Longbow'). This raises concerns about the generalizability of the rule sets to a wider range of VR applications or user demographics; and challenges in fully objective verification for all derived rules. | S38: The paper suggests that its findings provide a preliminary study for standardized VR user experience evaluation, indicating that further work is needed to develop a comprehensive standard using larger and more diverse samples, richer combinations of subjective and physiological measures to move towards a more standardised, generalisable VR UX evaluation framework and provide stronger design guidelines for VR content creators. | T38: A.Abdulhamid
